Workbook
Name Slicer_role_name: #N/A

Sheet dashboard
H4: DOTA 2 APRIL 2026 PRO MATCHES ANALYSIS
C8: Tracking the meta: picks, bans, wins, and top performers
D11: TOTAL MATCHES | Y11: TOTAL HEROES | AS11: QUALIFIED TEAMS
D12: 2378 | Y12: 128 | AS12: 97
D14: April 2026 | Y14: Tracked in Data Set | AS14: 10+ Matches Played
D17: MOST PICKED HEROES | AI17: MOST BANNED HEROES
D38: BEST PERFORMING HERO PER ROLE
D40: "Top 6 heroes per role ranked by win rate, minimum 10 matches played."
D42: CARRY | P42: MID | AB42: OFF LANE | AN42: SOFT SUPPORT | AZ42: HARD SUPPORT
E44: {=_xlfn.SORTBY(_xlfn._xlws.FILTER(hero_lane_summary!A2:A541,(hero_lane_summary!B2:B541="Carry")*(hero_lane_summary!F2:F541="Yes")*(hero_lane_summary!E2:E541>=LARGE(IF((hero_lane_summary!B2:B541="Carry")*(hero_lane_summary!F2:F541="Yes"),hero_lane_summary!E2:E541),6))),_xlfn._xlws.FILTER(hero_lane_summary!E2:E541,(hero_lane_summary!B2:B541="Carry")*(hero_lane_summary!F2:F541="Yes")*(hero_lane_summary!E2:E541>=LARGE(IF((hero_lane_summary!B2:B541="Carry")*(hero_lane_summary!F2:F541="Yes"),hero_lane_summary!E2:E541),6))),-1)} -> Pudge | J44: {=_xlfn.XLOOKUP(E44&"Carry",hero_lane_summary!A:A&hero_lane_summary!B:B,hero_lane_summary!E:E)} -> 0.81818182 | L44: {=_xlfn.XLOOKUP(E44&"Carry",hero_lane_summary!A:A&hero_lane_summary!B:B, hero_lane_summary!H:H)} -> S | Q44: {=_xlfn.SORTBY(_xlfn._xlws.FILTER(hero_lane_summary!A2:A541,(hero_lane_summary!B2:B541="Mid")*(hero_lane_summary!F2:F541="Yes")*(hero_lane_summary!E2:E541>=LARGE(IF((hero_lane_summary!B2:B541="Mid")*(hero_lane_summary!F2:F541="Yes"),hero_lane_summary!E2:E541),6))),_xlfn._xlws.FILTER(hero_lane_summary!E2:E541,(hero_lane_summary!B2:B541="Mid")*(hero_lane_summary!F2:F541="Yes")*(hero_lane_summary!E2:E541>=LARGE(IF((hero_lane_summary!B2:B541="Mid")*(hero_lane_summary!F2:F541="Yes"),hero_lane_summary!E2:E541),6))),-1)} -> Spirit Breaker | V44: {=_xlfn.XLOOKUP(Q44&"Mid",hero_lane_summary!A:A&hero_lane_summary!B:B,hero_lane_summary!E:E)} -> 0.8 | X44: {=_xlfn.XLOOKUP(Q44&"Mid",hero_lane_summary!A:A&hero_lane_summary!B:B, hero_lane_summary!H:H)} -> S | AC44: {=_xlfn.SORTBY( _xlfn._xlws.FILTER( hero_lane_summary!A2:A541, (hero_lane_summary!B2:B541="Off Lane")*(hero_lane_summary!F2:F541="Yes")* (hero_lane_summary!E2:E541>=LARGE(IF((hero_lane_summary!B2:B541="Off Lane")*(hero_lane_summary!F2:F541="Yes"),hero_lane_summary!E2:E541),6)) ), _xlfn._xlws.FILTER( hero_lane_summary!E2:E541, (hero_lane_summary!B2:B541="Off Lane")*(hero_lane_summary!F2:F541="Yes")* (hero_lane_summary!E2:E541>=LARGE(IF((hero_lane_summary!B2:B541="Off Lane")*(hero_lane_summary!F2:F541="Yes"),hero_lane_summary!E2:E541),6)) ),-1)} -> Zeus | AH44: {=_xlfn.XLOOKUP(AC44&"Off Lane",hero_lane_summary!A:A&hero_lane_summary!B:B,hero_lane_summary!E:E)} -> 0.73333333 | AJ44: {=_xlfn.XLOOKUP(AC44&"Off Lane",hero_lane_summary!A:A&hero_lane_summary!B:B, hero_lane_summary!H:H)} -> S | AO44: {=_xlfn.SORTBY(_xlfn._xlws.FILTER(hero_lane_summary!A2:A541,(hero_lane_summary!B2:B541="Soft Support")*(hero_lane_summary!F2:F541="Yes")*(hero_lane_summary!E2:E541>=LARGE(IF((hero_lane_summary!B2:B541="Soft Support")*(hero_lane_summary!F2:F541="Yes"),hero_lane_summary!E2:E541),6))),_xlfn._xlws.FILTER(hero_lane_summary!E2:E541,(hero_lane_summary!B2:B541="Soft Support")*(hero_lane_summary!F2:F541="Yes")*(hero_lane_summary!E2:E541>=LARGE(IF((hero_lane_summary!B2:B541="Soft Support")*(hero_lane_summary!F2:F541="Yes"),hero_lane_summary!E2:E541),6))),-1)} -> Bounty Hunter | AT44: {=_xlfn.XLOOKUP(AO44&"Soft Support",hero_lane_summary!A:A&hero_lane_summary!B:B,hero_lane_summary!E:E)} -> 0.75 | AV44: {=_xlfn.XLOOKUP(AO44&"Soft Support",hero_lane_summary!A:A&hero_lane_summary!B:B, hero_lane_summary!H:H)} -> S | BA44: {=_xlfn.SORTBY(_xlfn._xlws.FILTER(hero_lane_summary!A2:A541,(hero_lane_summary!B2:B541="Hard Support")*(hero_lane_summary!F2:F541="Yes")*(hero_lane_summary!E2:E541>=LARGE(IF((hero_lane_summary!B2:B541="Hard Support")*(hero_lane_summary!F2:F541="Yes"),hero_lane_summary!E2:E541),6))),_xlfn._xlws.FILTER(hero_lane_summary!E2:E541,(hero_lane_summary!B2:B541="Hard Support")*(hero_lane_summary!F2:F541="Yes")*(hero_lane_summary!E2:E541>=LARGE(IF((hero_lane_summary!B2:B541="Hard Support")*(hero_lane_summary!F2:F541="Yes"),hero_lane_summary!E2:E541),6))),-1)} -> Pugna | BF44: {=_xlfn.XLOOKUP(BA44&"Hard Support",hero_lane_summary!A:A&hero_lane_summary!B:B,hero_lane_summary!E:E)} -> 0.78571429 | BH44: {=_xlfn.XLOOKUP(BA44&"Hard Support",hero_lane_summary!A:A&hero_lane_summary!B:B, hero_lane_summary!H:H)} -> S
E45: Phoenix | J45: {=_xlfn.XLOOKUP(E45&"Carry",hero_lane_summary!A:A&hero_lane_summary!B:B,hero_lane_summary!E:E)} -> 0.7 | L45: {=_xlfn.XLOOKUP(E45&"Carry",hero_lane_summary!A:A&hero_lane_summary!B:B, hero_lane_summary!H:H)} -> S | Q45: Bristleback | V45: {=_xlfn.XLOOKUP(Q45&"Mid",hero_lane_summary!A:A&hero_lane_summary!B:B,hero_lane_summary!E:E)} -> 0.72727273 | X45: {=_xlfn.XLOOKUP(Q45&"Mid",hero_lane_summary!A:A&hero_lane_summary!B:B, hero_lane_summary!H:H)} -> S | AC45: Phoenix | AH45: {=_xlfn.XLOOKUP(AC45&"Off Lane",hero_lane_summary!A:A&hero_lane_summary!B:B,hero_lane_summary!E:E)} -> 0.73195876 | AJ45: {=_xlfn.XLOOKUP(AC45&"Off Lane",hero_lane_summary!A:A&hero_lane_summary!B:B, hero_lane_summary!H:H)} -> S | AO45: Earth Spirit | AT45: {=_xlfn.XLOOKUP(AO45&"Soft Support",hero_lane_summary!A:A&hero_lane_summary!B:B,hero_lane_summary!E:E)} -> 0.73076923 | AV45: {=_xlfn.XLOOKUP(AO45&"Soft Support",hero_lane_summary!A:A&hero_lane_summary!B:B, hero_lane_summary!H:H)} -> S | BA45: Keeper of the Light | BF45: {=_xlfn.XLOOKUP(BA45&"Hard Support",hero_lane_summary!A:A&hero_lane_summary!B:B,hero_lane_summary!E:E)} -> 0.73333333 | BH45: {=_xlfn.XLOOKUP(BA45&"Hard Support",hero_lane_summary!A:A&hero_lane_summary!B:B, hero_lane_summary!H:H)} -> S
E46: Lone Druid | J46: {=_xlfn.XLOOKUP(E46&"Carry",hero_lane_summary!A:A&hero_lane_summary!B:B,hero_lane_summary!E:E)} -> 0.6509434 | L46: {=_xlfn.XLOOKUP(E46&"Carry",hero_lane_summary!A:A&hero_lane_summary!B:B, hero_lane_summary!H:H)} -> S | Q46: Snapfire | V46: {=_xlfn.XLOOKUP(Q46&"Mid",hero_lane_summary!A:A&hero_lane_summary!B:B,hero_lane_summary!E:E)} -> 0.65714286 | X46: {=_xlfn.XLOOKUP(Q46&"Mid",hero_lane_summary!A:A&hero_lane_summary!B:B, hero_lane_summary!H:H)} -> S | AC46: Ogre Magi | AH46: {=_xlfn.XLOOKUP(AC46&"Off Lane",hero_lane_summary!A:A&hero_lane_summary!B:B,hero_lane_summary!E:E)} -> 0.68181818 | AJ46: {=_xlfn.XLOOKUP(AC46&"Off Lane",hero_lane_summary!A:A&hero_lane_summary!B:B, hero_lane_summary!H:H)} -> S | AO46: Lina | AT46: {=_xlfn.XLOOKUP(AO46&"Soft Support",hero_lane_summary!A:A&hero_lane_summary!B:B,hero_lane_summary!E:E)} -> 0.7 | AV46: {=_xlfn.XLOOKUP(AO46&"Soft Support",hero_lane_summary!A:A&hero_lane_summary!B:B, hero_lane_summary!H:H)} -> S | BA46: Mirana | BF46: {=_xlfn.XLOOKUP(BA46&"Hard Support",hero_lane_summary!A:A&hero_lane_summary!B:B,hero_lane_summary!E:E)} -> 0.69230769 | BH46: {=_xlfn.XLOOKUP(BA46&"Hard Support",hero_lane_summary!A:A&hero_lane_summary!B:B, hero_lane_summary!H:H)} -> S
E47: Naga Siren | J47: {=_xlfn.XLOOKUP(E47&"Carry",hero_lane_summary!A:A&hero_lane_summary!B:B,hero_lane_summary!E:E)} -> 0.63333333 | L47: {=_xlfn.XLOOKUP(E47&"Carry",hero_lane_summary!A:A&hero_lane_summary!B:B, hero_lane_summary!H:H)} -> A | Q47: Alchemist | V47: {=_xlfn.XLOOKUP(Q47&"Mid",hero_lane_summary!A:A&hero_lane_summary!B:B,hero_lane_summary!E:E)} -> 0.625 | X47: {=_xlfn.XLOOKUP(Q47&"Mid",hero_lane_summary!A:A&hero_lane_summary!B:B, hero_lane_summary!H:H)} -> A | AC47: Batrider | AH47: {=_xlfn.XLOOKUP(AC47&"Off Lane",hero_lane_summary!A:A&hero_lane_summary!B:B,hero_lane_summary!E:E)} -> 0.63694268 | AJ47: {=_xlfn.XLOOKUP(AC47&"Off Lane",hero_lane_summary!A:A&hero_lane_summary!B:B, hero_lane_summary!H:H)} -> A | AO47: Largo | AT47: {=_xlfn.XLOOKUP(AO47&"Soft Support",hero_lane_summary!A:A&hero_lane_summary!B:B,hero_lane_summary!E:E)} -> 0.6875 | AV47: {=_xlfn.XLOOKUP(AO47&"Soft Support",hero_lane_summary!A:A&hero_lane_summary!B:B, hero_lane_summary!H:H)} -> S | BA47: Windranger | BF47: {=_xlfn.XLOOKUP(BA47&"Hard Support",hero_lane_summary!A:A&hero_lane_summary!B:B,hero_lane_summary!E:E)} -> 0.66666667 | BH47: {=_xlfn.XLOOKUP(BA47&"Hard Support",hero_lane_summary!A:A&hero_lane_summary!B:B, hero_lane_summary!H:H)} -> S
E48: Sniper | J48: {=_xlfn.XLOOKUP(E48&"Carry",hero_lane_summary!A:A&hero_lane_summary!B:B,hero_lane_summary!E:E)} -> 0.60784314 | L48: {=_xlfn.XLOOKUP(E48&"Carry",hero_lane_summary!A:A&hero_lane_summary!B:B, hero_lane_summary!H:H)} -> A | Q48: Arc Warden | V48: {=_xlfn.XLOOKUP(Q48&"Mid",hero_lane_summary!A:A&hero_lane_summary!B:B,hero_lane_summary!E:E)} -> 0.61538462 | X48: {=_xlfn.XLOOKUP(Q48&"Mid",hero_lane_summary!A:A&hero_lane_summary!B:B, hero_lane_summary!H:H)} -> A | AC48: Necrophos | AH48: {=_xlfn.XLOOKUP(AC48&"Off Lane",hero_lane_summary!A:A&hero_lane_summary!B:B,hero_lane_summary!E:E)} -> 0.62962963 | AJ48: {=_xlfn.XLOOKUP(AC48&"Off Lane",hero_lane_summary!A:A&hero_lane_summary!B:B, hero_lane_summary!H:H)} -> A | AO48: Bane | AT48: {=_xlfn.XLOOKUP(AO48&"Soft Support",hero_lane_summary!A:A&hero_lane_summary!B:B,hero_lane_summary!E:E)} -> 0.68181818 | AV48: {=_xlfn.XLOOKUP(AO48&"Soft Support",hero_lane_summary!A:A&hero_lane_summary!B:B, hero_lane_summary!H:H)} -> S | BA48: Phoenix | BF48: {=_xlfn.XLOOKUP(BA48&"Hard Support",hero_lane_summary!A:A&hero_lane_summary!B:B,hero_lane_summary!E:E)} -> 0.65882353 | BH48: {=_xlfn.XLOOKUP(BA48&"Hard Support",hero_lane_summary!A:A&hero_lane_summary!B:B, hero_lane_summary!H:H)} -> S
E49: Necrophos | J49: {=_xlfn.XLOOKUP(E49&"Carry",hero_lane_summary!A:A&hero_lane_summary!B:B,hero_lane_summary!E:E)} -> 0.60714286 | L49: {=_xlfn.XLOOKUP(E49&"Carry",hero_lane_summary!A:A&hero_lane_summary!B:B, hero_lane_summary!H:H)} -> A | Q49: Clinkz | V49: {=_xlfn.XLOOKUP(Q49&"Mid",hero_lane_summary!A:A&hero_lane_summary!B:B,hero_lane_summary!E:E)} -> 0.61538462 | X49: {=_xlfn.XLOOKUP(Q49&"Mid",hero_lane_summary!A:A&hero_lane_summary!B:B, hero_lane_summary!H:H)} -> A | AC49: Visage | AH49: {=_xlfn.XLOOKUP(AC49&"Off Lane",hero_lane_summary!A:A&hero_lane_summary!B:B,hero_lane_summary!E:E)} -> 0.61904762 | AJ49: {=_xlfn.XLOOKUP(AC49&"Off Lane",hero_lane_summary!A:A&hero_lane_summary!B:B, hero_lane_summary!H:H)} -> A | AO49: Monkey King | AT49: {=_xlfn.XLOOKUP(AO49&"Soft Support",hero_lane_summary!A:A&hero_lane_summary!B:B,hero_lane_summary!E:E)} -> 0.64285714 | AV49: {=_xlfn.XLOOKUP(AO49&"Soft Support",hero_lane_summary!A:A&hero_lane_summary!B:B, hero_lane_summary!H:H)} -> A | BA49: Batrider | BF49: {=_xlfn.XLOOKUP(BA49&"Hard Support",hero_lane_summary!A:A&hero_lane_summary!B:B,hero_lane_summary!E:E)} -> 0.64285714 | BH49: {=_xlfn.XLOOKUP(BA49&"Hard Support",hero_lane_summary!A:A&hero_lane_summary!B:B, hero_lane_summary!H:H)} -> A
D53: BEST PERFORMING TEAM DURING PGL WALLACHIA SEASON 8
D73: BEST PERFORMING PLAYERS PER ROLE
D75: "Top 6 players per role ranked by win rate during PGL"
D77: CARRY | X77: MID | AR77: OFF LANE
E79: {=INDEX( _xlfn.SORTBY( _xlfn._xlws.FILTER( player_summary!A2:A220, (player_summary!D2:D220="Carry")* (player_summary!G2:G220="Yes") ), _xlfn._xlws.FILTER( player_summary!F2:F220, (player_summary!D2:D220="Carry")* (player_summary!G2:G220="Yes") ), -1 ), _xlfn.SEQUENCE(6) )} -> Kiritych~ | J79: {=_xlfn.XLOOKUP( 1, (TEXT(player_summary!A2:A220,"@")=TEXT(E79,"@"))* (player_summary!D2:D220="Carry"), player_summary!B2:B220 )} -> Monkey King | P79: {=_xlfn.XLOOKUP(1,(player_summary!$A$2:$A$220=E79&"")*(player_summary!$D$2:$D$220="Carry")*(player_summary!$B$2:$B$220=J79),player_summary!$H$2:$H$220)} -> 751.47059 | R79: {=_xlfn.XLOOKUP(1,(player_summary!$A$2:$A$220=E79&"")*(player_summary!$D$2:$D$220="Carry")*(player_summary!$B$2:$B$220=J79),player_summary!$I$2:$I$220)} -> 875.5 | T79: {=_xlfn.XLOOKUP(1,(player_summary!$A$2:$A$220=E79&"")*(player_summary!$D$2:$D$220="Carry")*(player_summary!$B$2:$B$220=J79),player_summary!$F$2:$F$220)} -> 0.79411765 | Y79: {=INDEX( _xlfn.SORTBY( _xlfn._xlws.FILTER( player_summary!A2:A220, (player_summary!D2:D220="Mid")* (player_summary!G2:G220="Yes") ), _xlfn._xlws.FILTER( player_summary!F2:F220, (player_summary!D2:D220="Mid")* (player_summary!G2:G220="Yes") ), -1 ), _xlfn.SEQUENCE(6) )} -> gpk~ | AD79: {=_xlfn.XLOOKUP( 1, (TEXT(player_summary!A2:A220,"@")=TEXT(Y79,"@"))* (player_summary!D2:D220="Mid"), player_summary!B2:B220 )} -> Pangolier | AJ79: {=_xlfn.XLOOKUP(1,(player_summary!$A$2:$A$220=Y79&"")*(player_summary!$D$2:$D$220="Mid")*(player_summary!$B$2:$B$220=AD79),player_summary!$H$2:$H$220)} -> 643.44118 | AL79: {=_xlfn.XLOOKUP(1,(player_summary!$A$2:$A$220=Y79&"")*(player_summary!$D$2:$D$220="Mid")*(player_summary!$B$2:$B$220=AD79),player_summary!$I$2:$I$220)} -> 851.08824 | AN79: {=_xlfn.XLOOKUP(1,(player_summary!$A$2:$A$220=Y79&"")*(player_summary!$D$2:$D$220="Mid")*(player_summary!$B$2:$B$220=AD79),player_summary!$F$2:$F$220)} -> 0.79411765 | AS79: {=INDEX( _xlfn.SORTBY( _xlfn._xlws.FILTER( player_summary!A2:A220, (player_summary!D2:D220="Off Lane")* (player_summary!G2:G220="Yes") ), _xlfn._xlws.FILTER( player_summary!F2:F220, (player_summary!D2:D220="Off Lane")* (player_summary!G2:G220="Yes") ), -1 ), _xlfn.SEQUENCE(6) )} -> MieRo | AX79: {=_xlfn.XLOOKUP( 1, (TEXT(player_summary!A2:A220,"@")=TEXT(AS79,"@"))* (player_summary!D2:D220="Off Lane"), player_summary!B2:B220 )} -> Dawnbreaker | BD79: {=_xlfn.XLOOKUP(1,(player_summary!$A$2:$A$220=AS79&"")*(player_summary!$D$2:$D$220="Off Lane")*(player_summary!$B$2:$B$220=AX79),player_summary!$H$2:$H$220)} -> 624.61765 | BF79: {=_xlfn.XLOOKUP(1,(player_summary!$A$2:$A$220=AS79&"")*(player_summary!$D$2:$D$220="Off Lane")*(player_summary!$B$2:$B$220=AX79),player_summary!$I$2:$I$220)} -> 817.05882 | BH79: {=_xlfn.XLOOKUP(1,(player_summary!$A$2:$A$220=Y79&"")*(player_summary!$D$2:$D$220="Mid")*(player_summary!$B$2:$B$220=AD79),player_summary!$F$2:$F$220)} -> 0.79411765
E80: Satanic | J80: {=_xlfn.XLOOKUP( 1, (TEXT(player_summary!A3:A221,"@")=TEXT(E80,"@"))* (player_summary!D3:D221="Carry"), player_summary!B3:B221 )} -> Kez | P80: {=_xlfn.XLOOKUP(1,(player_summary!$A$2:$A$220=E80&"")*(player_summary!$D$2:$D$220="Carry")*(player_summary!$B$2:$B$220=J80),player_summary!$H$2:$H$220)} -> 779.45161 | R80: {=_xlfn.XLOOKUP(1,(player_summary!$A$2:$A$220=E80&"")*(player_summary!$D$2:$D$220="Carry")*(player_summary!$B$2:$B$220=J80),player_summary!$I$2:$I$220)} -> 865.67742 | T80: {=_xlfn.XLOOKUP(1,(player_summary!$A$2:$A$220=E80&"")*(player_summary!$D$2:$D$220="Carry")*(player_summary!$B$2:$B$220=J80),player_summary!$F$2:$F$220)} -> 0.74193548 | Y80: No[o]ne- | AD80: {=_xlfn.XLOOKUP( 1, (TEXT(player_summary!A3:A221,"@")=TEXT(Y80,"@"))* (player_summary!D3:D221="Mid"), player_summary!B3:B221 )} -> Puck | AJ80: {=_xlfn.XLOOKUP(1,(player_summary!$A$2:$A$220=Y80&"")*(player_summary!$D$2:$D$220="Mid")*(player_summary!$B$2:$B$220=AD80),player_summary!$H$2:$H$220)} -> 606.32258 | AL80: {=_xlfn.XLOOKUP(1,(player_summary!$A$2:$A$220=Y80&"")*(player_summary!$D$2:$D$220="Mid")*(player_summary!$B$2:$B$220=AD80),player_summary!$I$2:$I$220)} -> 753.83871 | AN80: {=_xlfn.XLOOKUP(1,(player_summary!$A$2:$A$220=Y80&"")*(player_summary!$D$2:$D$220="Mid")*(player_summary!$B$2:$B$220=AD80),player_summary!$F$2:$F$220)} -> 0.74193548 | AS80: SSS | AX80: {=_xlfn.XLOOKUP( 1, (TEXT(player_summary!A3:A221,"@")=TEXT(AS80,"@"))* (player_summary!D3:D221="Off Lane"), player_summary!B3:B221 )} -> Slardar | BD80: {=_xlfn.XLOOKUP(1,(player_summary!$A$2:$A$220=AS80&"")*(player_summary!$D$2:$D$220="Off Lane")*(player_summary!$B$2:$B$220=AX80),player_summary!$H$2:$H$220)} -> 544.80645 | BF80: {=_xlfn.XLOOKUP(1,(player_summary!$A$2:$A$220=AS80&"")*(player_summary!$D$2:$D$220="Off Lane")*(player_summary!$B$2:$B$220=AX80),player_summary!$I$2:$I$220)} -> 674.19355 | BH80: {=_xlfn.XLOOKUP(1,(player_summary!$A$2:$A$220=Y80&"")*(player_summary!$D$2:$D$220="Mid")*(player_summary!$B$2:$B$220=AD80),player_summary!$F$2:$F$220)} -> 0.74193548
E81: 423 | J81: {=_xlfn.XLOOKUP(1,(player_summary!A2:A220=E81&"")*(player_summary!D2:D220="Carry"),player_summary!B2:B220)} -> Terrorblade | P81: {=_xlfn.XLOOKUP(1,(player_summary!$A$2:$A$220=E81&"")*(player_summary!$D$2:$D$220="Carry")*(player_summary!$B$2:$B$220=J81),player_summary!$H$2:$H$220)} -> 758.81481 | R81: {=_xlfn.XLOOKUP(1,(player_summary!$A$2:$A$220=E81&"")*(player_summary!$D$2:$D$220="Carry")*(player_summary!$B$2:$B$220=J81),player_summary!$I$2:$I$220)} -> 846.55556 | T81: {=_xlfn.XLOOKUP(1,(player_summary!$A$2:$A$220=E81&"")*(player_summary!$D$2:$D$220="Carry")*(player_summary!$B$2:$B$220=J81),player_summary!$F$2:$F$220)} -> 0.7037037 | Y81: Tala | AD81: {=_xlfn.XLOOKUP( 1, (TEXT(player_summary!A4:A222,"@")=TEXT(Y81,"@"))* (player_summary!D4:D222="Mid"), player_summary!B4:B222 )} -> Tiny | AJ81: {=_xlfn.XLOOKUP(1,(player_summary!$A$2:$A$220=Y81&"")*(player_summary!$D$2:$D$220="Mid")*(player_summary!$B$2:$B$220=AD81),player_summary!$H$2:$H$220)} -> 536.45455 | AL81: {=_xlfn.XLOOKUP(1,(player_summary!$A$2:$A$220=Y81&"")*(player_summary!$D$2:$D$220="Mid")*(player_summary!$B$2:$B$220=AD81),player_summary!$I$2:$I$220)} -> 674.90909 | AN81: {=_xlfn.XLOOKUP(1,(player_summary!$A$2:$A$220=Y81&"")*(player_summary!$D$2:$D$220="Mid")*(player_summary!$B$2:$B$220=AD81),player_summary!$F$2:$F$220)} -> 0.72727273 | AS81: Fbz | AX81: {=_xlfn.XLOOKUP( 1, (TEXT(player_summary!A4:A222,"@")=TEXT(AS81,"@"))* (player_summary!D4:D222="Off Lane"), player_summary!B4:B222 )} -> Bristleback | BD81: {=_xlfn.XLOOKUP(1,(player_summary!$A$2:$A$220=AS81&"")*(player_summary!$D$2:$D$220="Off Lane")*(player_summary!$B$2:$B$220=AX81),player_summary!$H$2:$H$220)} -> 568.28571 | BF81: {=_xlfn.XLOOKUP(1,(player_summary!$A$2:$A$220=AS81&"")*(player_summary!$D$2:$D$220="Off Lane")*(player_summary!$B$2:$B$220=AX81),player_summary!$I$2:$I$220)} -> 760.42857 | BH81: {=_xlfn.XLOOKUP(1,(player_summary!$A$2:$A$220=Y81&"")*(player_summary!$D$2:$D$220="Mid")*(player_summary!$B$2:$B$220=AD81),player_summary!$F$2:$F$220)} -> 0.72727273
E82: rincyq | J82: {=_xlfn.XLOOKUP( 1, (TEXT(player_summary!A5:A223,"@")=TEXT(E82,"@"))* (player_summary!D5:D223="Carry"), player_summary!B5:B223 )} -> Muerta | P82: {=_xlfn.XLOOKUP(1,(player_summary!$A$2:$A$220=E82&"")*(player_summary!$D$2:$D$220="Carry")*(player_summary!$B$2:$B$220=J82),player_summary!$H$2:$H$220)} -> 704.38776 | R82: {=_xlfn.XLOOKUP(1,(player_summary!$A$2:$A$220=E82&"")*(player_summary!$D$2:$D$220="Carry")*(player_summary!$B$2:$B$220=J82),player_summary!$I$2:$I$220)} -> 819.83673 | T82: {=_xlfn.XLOOKUP(1,(player_summary!$A$2:$A$220=E82&"")*(player_summary!$D$2:$D$220="Carry")*(player_summary!$B$2:$B$220=J82),player_summary!$F$2:$F$220)} -> 0.69387755 | Y82: inYourdreaM | AD82: {=_xlfn.XLOOKUP( 1, (TEXT(player_summary!A5:A223,"@")=TEXT(Y82,"@"))* (player_summary!D5:D223="Mid"), player_summary!B5:B223 )} -> Sand King | AJ82: {=_xlfn.XLOOKUP(1,(player_summary!$A$2:$A$220=Y82&"")*(player_summary!$D$2:$D$220="Mid")*(player_summary!$B$2:$B$220=AD82),player_summary!$H$2:$H$220)} -> 580.61905 | AL82: {=_xlfn.XLOOKUP(1,(player_summary!$A$2:$A$220=Y82&"")*(player_summary!$D$2:$D$220="Mid")*(player_summary!$B$2:$B$220=AD82),player_summary!$I$2:$I$220)} -> 738.33333 | AN82: {=_xlfn.XLOOKUP(1,(player_summary!$A$2:$A$220=Y82&"")*(player_summary!$D$2:$D$220="Mid")*(player_summary!$B$2:$B$220=AD82),player_summary!$F$2:$F$220)} -> 0.71428571 | AS82: laise | AX82: {=_xlfn.XLOOKUP( 1, (TEXT(player_summary!A5:A223,"@")=TEXT(AS82,"@"))* (player_summary!D5:D223="Off Lane"), player_summary!B5:B223 )} -> Brewmaster | BD82: {=_xlfn.XLOOKUP(1,(player_summary!$A$2:$A$220=AS82&"")*(player_summary!$D$2:$D$220="Off Lane")*(player_summary!$B$2:$B$220=AX82),player_summary!$H$2:$H$220)} -> 575.42424 | BF82: {=_xlfn.XLOOKUP(1,(player_summary!$A$2:$A$220=AS82&"")*(player_summary!$D$2:$D$220="Off Lane")*(player_summary!$B$2:$B$220=AX82),player_summary!$I$2:$I$220)} -> 739.36364 | BH82: {=_xlfn.XLOOKUP(1,(player_summary!$A$2:$A$220=Y82&"")*(player_summary!$D$2:$D$220="Mid")*(player_summary!$B$2:$B$220=AD82),player_summary!$F$2:$F$220)} -> 0.71428571
E83: shigetsu | J83: {=_xlfn.XLOOKUP( 1, (TEXT(player_summary!A6:A224,"@")=TEXT(E83,"@"))* (player_summary!D6:D224="Carry"), player_summary!B6:B224 )} -> Luna | P83: {=_xlfn.XLOOKUP(1,(player_summary!$A$2:$A$220=E83&"")*(player_summary!$D$2:$D$220="Carry")*(player_summary!$B$2:$B$220=J83),player_summary!$H$2:$H$220)} -> 799.44828 | R83: {=_xlfn.XLOOKUP(1,(player_summary!$A$2:$A$220=E83&"")*(player_summary!$D$2:$D$220="Carry")*(player_summary!$B$2:$B$220=J83),player_summary!$I$2:$I$220)} -> 912.2069 | T83: {=_xlfn.XLOOKUP(1,(player_summary!$A$2:$A$220=E83&"")*(player_summary!$D$2:$D$220="Carry")*(player_summary!$B$2:$B$220=J83),player_summary!$F$2:$F$220)} -> 0.68965517 | Y83: No!obâ„¢ | AD83: {=_xlfn.XLOOKUP( 1, (TEXT(player_summary!A6:A224,"@")=TEXT(Y83,"@"))* (player_summary!D6:D224="Mid"), player_summary!B6:B224 )} -> Beastmaster | AJ83: {=_xlfn.XLOOKUP(1,(player_summary!$A$2:$A$220=Y83&"")*(player_summary!$D$2:$D$220="Mid")*(player_summary!$B$2:$B$220=AD83),player_summary!$H$2:$H$220)} -> 614.14286 | AL83: {=_xlfn.XLOOKUP(1,(player_summary!$A$2:$A$220=Y83&"")*(player_summary!$D$2:$D$220="Mid")*(player_summary!$B$2:$B$220=AD83),player_summary!$I$2:$I$220)} -> 773.38776 | AN83: {=_xlfn.XLOOKUP(1,(player_summary!$A$2:$A$220=Y83&"")*(player_summary!$D$2:$D$220="Mid")*(player_summary!$B$2:$B$220=AD83),player_summary!$F$2:$F$220)} -> 0.69387755 | AS83: Davai Lama | AX83: {=_xlfn.XLOOKUP( 1, (TEXT(player_summary!A6:A224,"@")=TEXT(AS83,"@"))* (player_summary!D6:D224="Off Lane"), player_summary!B6:B224 )} -> Underlord | BD83: {=_xlfn.XLOOKUP(1,(player_summary!$A$2:$A$220=AS83&"")*(player_summary!$D$2:$D$220="Off Lane")*(player_summary!$B$2:$B$220=AX83),player_summary!$H$2:$H$220)} -> 556.70213 | BF83: {=_xlfn.XLOOKUP(1,(player_summary!$A$2:$A$220=AS83&"")*(player_summary!$D$2:$D$220="Off Lane")*(player_summary!$B$2:$B$220=AX83),player_summary!$I$2:$I$220)} -> 717.93617 | BH83: {=_xlfn.XLOOKUP(1,(player_summary!$A$2:$A$220=Y83&"")*(player_summary!$D$2:$D$220="Mid")*(player_summary!$B$2:$B$220=AD83),player_summary!$F$2:$F$220)} -> 0.69387755
E84: 23savage | J84: {=_xlfn.XLOOKUP(1,(player_summary!A2:A220=E84&"")*(player_summary!D2:D220="Carry"),player_summary!B2:B220)} -> Ursa | P84: {=_xlfn.XLOOKUP(1,(player_summary!$A$2:$A$220=E84&"")*(player_summary!$D$2:$D$220="Carry")*(player_summary!$B$2:$B$220=J84),player_summary!$H$2:$H$220)} -> 698.77778 | R84: {=_xlfn.XLOOKUP(1,(player_summary!$A$2:$A$220=E84&"")*(player_summary!$D$2:$D$220="Carry")*(player_summary!$B$2:$B$220=J84),player_summary!$I$2:$I$220)} -> 855 | T84: {=_xlfn.XLOOKUP(1,(player_summary!$A$2:$A$220=E84&"")*(player_summary!$D$2:$D$220="Carry")*(player_summary!$B$2:$B$220=J84),player_summary!$F$2:$F$220)} -> 0.66666667 | Y84: EchozZ | AD84: {=_xlfn.XLOOKUP( 1, (TEXT(player_summary!A7:A225,"@")=TEXT(Y84,"@"))* (player_summary!D7:D225="Mid"), player_summary!B7:B225 )} -> Sand King | AJ84: {=_xlfn.XLOOKUP(1,(player_summary!$A$2:$A$220=Y84&"")*(player_summary!$D$2:$D$220="Mid")*(player_summary!$B$2:$B$220=AD84),player_summary!$H$2:$H$220)} -> 549.33333 | AL84: {=_xlfn.XLOOKUP(1,(player_summary!$A$2:$A$220=Y84&"")*(player_summary!$D$2:$D$220="Mid")*(player_summary!$B$2:$B$220=AD84),player_summary!$I$2:$I$220)} -> 693.26667 | AN84: {=_xlfn.XLOOKUP(1,(player_summary!$A$2:$A$220=Y84&"")*(player_summary!$D$2:$D$220="Mid")*(player_summary!$B$2:$B$220=AD84),player_summary!$F$2:$F$220)} -> 0.66666667 | AS84: Jabz | AX84: {=_xlfn.XLOOKUP( 1, (TEXT(player_summary!A7:A225,"@")=TEXT(AS84,"@"))* (player_summary!D7:D225="Off Lane"), player_summary!B7:B225 )} -> Slardar | BD84: {=_xlfn.XLOOKUP(1,(player_summary!$A$2:$A$220=AS84&"")*(player_summary!$D$2:$D$220="Off Lane")*(player_summary!$B$2:$B$220=AX84),player_summary!$H$2:$H$220)} -> 539.55556 | BF84: {=_xlfn.XLOOKUP(1,(player_summary!$A$2:$A$220=AS84&"")*(player_summary!$D$2:$D$220="Off Lane")*(player_summary!$B$2:$B$220=AX84),player_summary!$I$2:$I$220)} -> 745.77778 | BH84: {=_xlfn.XLOOKUP(1,(player_summary!$A$2:$A$220=Y84&"")*(player_summary!$D$2:$D$220="Mid")*(player_summary!$B$2:$B$220=AD84),player_summary!$F$2:$F$220)} -> 0.66666667
N87: SOFT SUPPORT | AH87: HARD SUPPORT
O89: {=INDEX( _xlfn.SORTBY( _xlfn._xlws.FILTER( player_summary!A2:A220, (player_summary!D2:D220="Soft Support")* (player_summary!G2:G220="Yes") ), _xlfn._xlws.FILTER( player_summary!F2:F220, (player_summary!D2:D220="Soft Support")* (player_summary!G2:G220="Yes") ), -1 ), _xlfn.SEQUENCE(6) )} -> Save- | S89: {=_xlfn.XLOOKUP( 1, (TEXT(player_summary!A2:A220,"@")=TEXT(O89,"@"))* (player_summary!D2:D220="Soft Support"), player_summary!B2:B220 )} -> Hoodwink | Z89: {=_xlfn.XLOOKUP(1,(player_summary!$A$2:$A$220=O89&"")*(player_summary!$D$2:$D$220="Soft Support")*(player_summary!$B$2:$B$220=S89),player_summary!$H$2:$H$220)} -> 367.38235 | AB89: {=_xlfn.XLOOKUP(1,(player_summary!$A$2:$A$220=O89&"")*(player_summary!$D$2:$D$220="Soft Support")*(player_summary!$B$2:$B$220=S89),player_summary!$I$2:$I$220)} -> 571.67647 | AD89: {=_xlfn.XLOOKUP(1,(player_summary!$A$2:$A$220=O89&"")*(player_summary!$D$2:$D$220="Soft Support")*(player_summary!$B$2:$B$220=S89),player_summary!$F$2:$F$220)} -> 0.79411765 | AI89: {=INDEX( _xlfn.SORTBY( _xlfn._xlws.FILTER( player_summary!A2:A220, (player_summary!D2:D220="Hard Support")* (player_summary!G2:G220="Yes") ), _xlfn._xlws.FILTER( player_summary!F2:F220, (player_summary!D2:D220="Hard Support")* (player_summary!G2:G220="Yes") ), -1 ), _xlfn.SEQUENCE(6) )} -> Kataomi` | AN89: {=_xlfn.XLOOKUP( 1, (TEXT(player_summary!A2:A220,"@")=TEXT(AI89,"@"))* (player_summary!D2:D220="Hard Support"), player_summary!B2:B220 )} -> Lich | AT89: {=_xlfn.XLOOKUP(1,(player_summary!$A$2:$A$220=AI89&"")*(player_summary!$D$2:$D$220="Hard Support")*(player_summary!$B$2:$B$220=AN89),player_summary!$H$2:$H$220)} -> 362.85294 | AV89: {=_xlfn.XLOOKUP(1,(player_summary!$A$2:$A$220=AI89&"")*(player_summary!$D$2:$D$220="Hard Support")*(player_summary!$B$2:$B$220=AN89),player_summary!$I$2:$I$220)} -> 510.61765 | AX89: {=_xlfn.XLOOKUP(1,(player_summary!$A$2:$A$220=AI89&"")*(player_summary!$D$2:$D$220="Hard Support")*(player_summary!$B$2:$B$220=AN89),player_summary!$F$2:$F$220)} -> 0.79411765
O90: Varizh | S90: {=_xlfn.XLOOKUP( 1, (TEXT(player_summary!A3:A221,"@")=TEXT(O90,"@"))* (player_summary!D3:D221="Soft Support"), player_summary!B3:B221 )} -> Phoenix | Z90: {=_xlfn.XLOOKUP(1,(player_summary!$A$2:$A$220=O90&"")*(player_summary!$D$2:$D$220="Soft Support")*(player_summary!$B$2:$B$220=S90),player_summary!$H$2:$H$220)} -> 351.95238 | AB90: {=_xlfn.XLOOKUP(1,(player_summary!$A$2:$A$220=O90&"")*(player_summary!$D$2:$D$220="Soft Support")*(player_summary!$B$2:$B$220=S90),player_summary!$I$2:$I$220)} -> 494 | AD90: {=_xlfn.XLOOKUP(1,(player_summary!$A$2:$A$220=O90&"")*(player_summary!$D$2:$D$220="Soft Support")*(player_summary!$B$2:$B$220=S90),player_summary!$F$2:$F$220)} -> 0.71428571 | AI90: Dukalis | AN90: {=_xlfn.XLOOKUP( 1, (TEXT(player_summary!A3:A221,"@")=TEXT(AI90,"@"))* (player_summary!D3:D221="Hard Support"), player_summary!B3:B221 )} -> Phoenix | AT90: {=_xlfn.XLOOKUP(1,(player_summary!$A$2:$A$220=AI90&"")*(player_summary!$D$2:$D$220="Hard Support")*(player_summary!$B$2:$B$220=AN90),player_summary!$H$2:$H$220)} -> 359.77419 | AV90: {=_xlfn.XLOOKUP(1,(player_summary!$A$2:$A$220=AI90&"")*(player_summary!$D$2:$D$220="Hard Support")*(player_summary!$B$2:$B$220=AN90),player_summary!$I$2:$I$220)} -> 456.32258 | AX90: {=_xlfn.XLOOKUP(1,(player_summary!$A$2:$A$220=AI90&"")*(player_summary!$D$2:$D$220="Hard Support")*(player_summary!$B$2:$B$220=AN90),player_summary!$F$2:$F$220)} -> 0.74193548
O91: Carlo | S91: {=_xlfn.XLOOKUP( 1, (TEXT(player_summary!A4:A222,"@")=TEXT(O91,"@"))* (player_summary!D4:D222="Soft Support"), player_summary!B4:B222 )} -> Rubick | Z91: {=_xlfn.XLOOKUP(1,(player_summary!$A$2:$A$220=O91&"")*(player_summary!$D$2:$D$220="Soft Support")*(player_summary!$B$2:$B$220=S91),player_summary!$H$2:$H$220)} -> 381.8 | AB91: {=_xlfn.XLOOKUP(1,(player_summary!$A$2:$A$220=O91&"")*(player_summary!$D$2:$D$220="Soft Support")*(player_summary!$B$2:$B$220=S91),player_summary!$I$2:$I$220)} -> 515.7 | AD91: {=_xlfn.XLOOKUP(1,(player_summary!$A$2:$A$220=O91&"")*(player_summary!$D$2:$D$220="Soft Support")*(player_summary!$B$2:$B$220=S91),player_summary!$F$2:$F$220)} -> 0.7 | AI91: Se | AN91: {=_xlfn.XLOOKUP( 1, (TEXT(player_summary!A4:A222,"@")=TEXT(AI91,"@"))* (player_summary!D4:D222="Hard Support"), player_summary!B4:B222 )} -> Silencer | AT91: {=_xlfn.XLOOKUP(1,(player_summary!$A$2:$A$220=AI91&"")*(player_summary!$D$2:$D$220="Hard Support")*(player_summary!$B$2:$B$220=AN91),player_summary!$H$2:$H$220)} -> 358.30303 | AV91: {=_xlfn.XLOOKUP(1,(player_summary!$A$2:$A$220=AI91&"")*(player_summary!$D$2:$D$220="Hard Support")*(player_summary!$B$2:$B$220=AN91),player_summary!$I$2:$I$220)} -> 489.60606 | AX91: {=_xlfn.XLOOKUP(1,(player_summary!$A$2:$A$220=AI91&"")*(player_summary!$D$2:$D$220="Hard Support")*(player_summary!$B$2:$B$220=AN91),player_summary!$F$2:$F$220)} -> 0.6969697
O92: Fernans | S92: {=_xlfn.XLOOKUP( 1, (TEXT(player_summary!A5:A223,"@")=TEXT(O92,"@"))* (player_summary!D5:D223="Soft Support"), player_summary!B5:B223 )} -> Rubick | Z92: {=_xlfn.XLOOKUP(1,(player_summary!$A$2:$A$220=O92&"")*(player_summary!$D$2:$D$220="Soft Support")*(player_summary!$B$2:$B$220=S92),player_summary!$H$2:$H$220)} -> 348.21212 | AB92: {=_xlfn.XLOOKUP(1,(player_summary!$A$2:$A$220=O92&"")*(player_summary!$D$2:$D$220="Soft Support")*(player_summary!$B$2:$B$220=S92),player_summary!$I$2:$I$220)} -> 519.06061 | AD92: {=_xlfn.XLOOKUP(1,(player_summary!$A$2:$A$220=O92&"")*(player_summary!$D$2:$D$220="Soft Support")*(player_summary!$B$2:$B$220=S92),player_summary!$F$2:$F$220)} -> 0.6969697 | AI92: OmaR | AN92: {=_xlfn.XLOOKUP( 1, (TEXT(player_summary!A5:A223,"@")=TEXT(AI92,"@"))* (player_summary!D5:D223="Hard Support"), player_summary!B5:B223 )} -> Rubick | AT92: {=_xlfn.XLOOKUP(1,(player_summary!$A$2:$A$220=AI92&"")*(player_summary!$D$2:$D$220="Hard Support")*(player_summary!$B$2:$B$220=AN92),player_summary!$H$2:$H$220)} -> 342.55102 | AV92: {=_xlfn.XLOOKUP(1,(player_summary!$A$2:$A$220=AI92&"")*(player_summary!$D$2:$D$220="Hard Support")*(player_summary!$B$2:$B$220=AN92),player_summary!$I$2:$I$220)} -> 527.36735 | AX92: {=_xlfn.XLOOKUP(1,(player_summary!$A$2:$A$220=AI92&"")*(player_summary!$D$2:$D$220="Hard Support")*(player_summary!$B$2:$B$220=AN92),player_summary!$F$2:$F$220)} -> 0.69387755
O93: GH | S93: {=_xlfn.XLOOKUP( 1, (TEXT(player_summary!A6:A224,"@")=TEXT(O93,"@"))* (player_summary!D6:D224="Soft Support"), player_summary!B6:B224 )} -> Phoenix | Z93: {=_xlfn.XLOOKUP(1,(player_summary!$A$2:$A$220=O93&"")*(player_summary!$D$2:$D$220="Soft Support")*(player_summary!$B$2:$B$220=S93),player_summary!$H$2:$H$220)} -> 360.2449 | AB93: {=_xlfn.XLOOKUP(1,(player_summary!$A$2:$A$220=O93&"")*(player_summary!$D$2:$D$220="Soft Support")*(player_summary!$B$2:$B$220=S93),player_summary!$I$2:$I$220)} -> 488.02041 | AD93: {=_xlfn.XLOOKUP(1,(player_summary!$A$2:$A$220=O93&"")*(player_summary!$D$2:$D$220="Soft Support")*(player_summary!$B$2:$B$220=S93),player_summary!$F$2:$F$220)} -> 0.69387755 | AI93: Kiri < | AN93: {=_xlfn.XLOOKUP( 1, (TEXT(player_summary!A6:A224,"@")=TEXT(AI93,"@"))* (player_summary!D6:D224="Hard Support"), player_summary!B6:B224 )} -> Rubick | AT93: {=_xlfn.XLOOKUP(1,(player_summary!$A$2:$A$220=AI93&"")*(player_summary!$D$2:$D$220="Hard Support")*(player_summary!$B$2:$B$220=AN93),player_summary!$H$2:$H$220)} -> 381.11111 | AV93: {=_xlfn.XLOOKUP(1,(player_summary!$A$2:$A$220=AI93&"")*(player_summary!$D$2:$D$220="Hard Support")*(player_summary!$B$2:$B$220=AN93),player_summary!$I$2:$I$220)} -> 511.05556 | AX93: {=_xlfn.XLOOKUP(1,(player_summary!$A$2:$A$220=AI93&"")*(player_summary!$D$2:$D$220="Hard Support")*(player_summary!$B$2:$B$220=AN93),player_summary!$F$2:$F$220)} -> 0.66666667
O94: not me | S94: {=_xlfn.XLOOKUP( 1, (TEXT(player_summary!A7:A225,"@")=TEXT(O94,"@"))* (player_summary!D7:D225="Soft Support"), player_summary!B7:B225 )} -> Hoodwink | Z94: {=_xlfn.XLOOKUP(1,(player_summary!$A$2:$A$220=O94&"")*(player_summary!$D$2:$D$220="Soft Support")*(player_summary!$B$2:$B$220=S94),player_summary!$H$2:$H$220)} -> 362.10345 | AB94: {=_xlfn.XLOOKUP(1,(player_summary!$A$2:$A$220=O94&"")*(player_summary!$D$2:$D$220="Soft Support")*(player_summary!$B$2:$B$220=S94),player_summary!$I$2:$I$220)} -> 507.27586 | AD94: {=_xlfn.XLOOKUP(1,(player_summary!$A$2:$A$220=O94&"")*(player_summary!$D$2:$D$220="Soft Support")*(player_summary!$B$2:$B$220=S94),player_summary!$F$2:$F$220)} -> 0.68965517 | AI94: xNova | AN94: {=_xlfn.XLOOKUP( 1, (TEXT(player_summary!A7:A225,"@")=TEXT(AI94,"@"))* (player_summary!D7:D225="Hard Support"), player_summary!B7:B225 )} -> Phoenix | AT94: {=_xlfn.XLOOKUP(1,(player_summary!$A$2:$A$220=AI94&"")*(player_summary!$D$2:$D$220="Hard Support")*(player_summary!$B$2:$B$220=AN94),player_summary!$H$2:$H$220)} -> 337.83333 | AV94: {=_xlfn.XLOOKUP(1,(player_summary!$A$2:$A$220=AI94&"")*(player_summary!$D$2:$D$220="Hard Support")*(player_summary!$B$2:$B$220=AN94),player_summary!$I$2:$I$220)} -> 459.44444 | AX94: {=_xlfn.XLOOKUP(1,(player_summary!$A$2:$A$220=AI94&"")*(player_summary!$D$2:$D$220="Hard Support")*(player_summary!$B$2:$B$220=AN94),player_summary!$F$2:$F$220)} -> 0.66666667

Sheet player_summary
A1: name | B1: main_hero | C1: times_played | D1: lane | E1: times_won | F1: win_rate | G1: qualify | H1: avg_gpm | I1: avg_xpm
A2: 423 | B2: Terrorblade | C2: 27 | D2: Carry | E2: 19 | F2: 0.7037037 | G2: Yes | H2: 758.81481 | I2: 846.55556
A3: 999 | B3: Tusk | C3: 21 | D3: Hard Support | E3: 11 | F3: 0.52380952 | G3: Yes | H3: 305.90476 | I3: 427.33333
A4: chipikao | B4: Bristleback | C4: 13 | D4: Off Lane | E4: 4 | F4: 0.30769231 | G4: Yes | H4: 536.38462 | I4: 643.15385
A5: 23savage | B5: Ursa | C5: 18 | D5: Carry | E5: 12 | F5: 0.66666667 | G5: Yes | H5: 698.77778 | I5: 855
A6: 7eeeeeee | B6: Beastmaster | C6: 21 | D6: Mid | E6: 11 | F6: 0.52380952 | G6: Yes | H6: 521.47619 | I6: 671.61905
A7: 9Class | B7: Keeper of the Light | C7: 31 | D7: Roam | E7: 23 | F7: 0.74193548 | G7: Yes | H7: 402.90323 | I7: 511.3871
A8: å‘½é‹ reinprince | B8: Venomancer | C8: 50 | D8: Soft Support | E8: 24 | F8: 0.48 | G8: Yes | H8: 354.46 | I8: 421.66
A9: Abed | B9: Void Spirit | C9: 19 | D9: Mid | E9: 7 | F9: 0.36842105 | G9: Yes | H9: 563.10526 | I9: 702.89474
A10: AbyssWalker | B10: Ogre Magi | C10: 117 | D10: Hard Support | E10: 61 | F10: 0.52136752 | G10: Yes | H10: 309.08547 | I10: 461.89744
A11: Ace â™ | B11: Pangolier | C11: 38 | D11: Off Lane | E11: 23 | F11: 0.60526316 | G11: Yes | H11: 579.5 | I11: 799.26316
A12: æ¥¼ | B12: Kez | C12: 11 | D12: Carry | E12: 5 | F12: 0.45454545 | G12: Yes | H12: 740.63636 | I12: 804.90909
A13: aik | B13: Phoenix | C13: 35 | D13: Soft Support | E13: 15 | F13: 0.42857143 | G13: Yes | H13: 379.97143 | I13: 483.05714
A14: Ainkrad | B14: Puck | C14: 3 | D14: Mid | E14: 1 | F14: 0.33333333 | G14: No | H14: 511.66667 | I14: 599
A15: Akamu | B15: Jakiro | C15: 13 | D15: Hard Support | E15: 4 | F15: 0.30769231 | G15: Yes | H15: 344.23077 | I15: 433.61538
... A220: zzq | B220: Treant Protector | C220: 15 | D220: Hard Support | E220: 10 | F220: 0.66666667 | G220: Yes | H220: 309.66667 | I220: 448.06667

Sheet team_summary
A1: team_name | B1: times_played | C1: times_won | D1: win_rate | E1: qualify
A2: rostov radost | B2: 0 | C2: 0 | D2: #DIV/0! | E2: No
A3: Prime Time | B3: 0 | C3: 0 | D3: #DIV/0! | E3: No
A4: Enjoy | B4: 0 | C4: 0 | D4: #DIV/0! | E4: No
A5: fp anti-mage | B5: 1 | C5: 1 | D5: 1 | E5: No
A6: Ð¿Ð¾Ð²ÐµÑ€ Ñ€ÐµÐ½Ð´Ð¶ÐµÑ€Ñ | B6: 2 | C6: 2 | D6: 1 | E6: No
A7: TEAM TpaBoMaH | B7: 1 | C7: 1 | D7: 1 | E7: No
A8: VMYASO TEAM | B8: 1 | C8: 1 | D8: 1 | E8: No
A9: BOCEMHAXA | B9: 1 | C9: 1 | D9: 1 | E9: No
A10: OnlyGuapos | B10: 1 | C10: 1 | D10: 1 | E10: No
A11: Acatsuki | B11: 1 | C11: 1 | D11: 1 | E11: No
A12: EHOME SA | B12: 1 | C12: 1 | D12: 1 | E12: No
A13: BIZCOCHOS KARIM | B13: 1 | C13: 1 | D13: 1 | E13: No
A14: LAVA SPORTS | B14: 1 | C14: 1 | D14: 1 | E14: No
A15: xd | B15: 1 | C15: 1 | D15: 1 | E15: No
A16: MightyGods | B16: 4 | C16: 4 | D16: 1 | E16: No
... A41: Ð–Ð¸Ñ€Ð½Ñ‹Ðµ Ð”ÐµÑ‚Ð¸ Ð² Ð”ÐµÐ¿Ñ€ÐµÑÑÐ¸Ð¸ | B41: 2 | C41: 1 | D41: 0.5 | E41: No
A42: 22312 | B42: 2 | C42: 1 | D42: 0.5 | E42: No
A43: Raidd Boss | B43: 2 | C43: 1 | D43: 0.5 | E43: No
A44: La Passion | B44: 2 | C44: 1 | D44: 0.5 | E44: No
A45: ShIShulI | B45: 6 | C45: 3 | D45: 0.5 | E45: No
A46: Nigma Galaxy | B46: 49 | C46: 23 | D46: 0.46938776 | E46: Yes
A47: L1GA TEAM | B47: 61 | C47: 28 | D47: 0.45901639 | E47: Yes
A48: Team Antares | B48: 11 | C48: 5 | D48: 0.45454545 | E48: Yes
A49: GLYPH | B49: 23 | C49: 10 | D49: 0.43478261 | E49: Yes
A50: Fortnite | B50: 7 | C50: 3 | D50: 0.42857143 | E50: No
A51: loodowolfs | B51: 7 | C51: 3 | D51: 0.42857143 | E51: No
A52: Team Nemesis | B52: 17 | C52: 7 | D52: 0.41176471 | E52: Yes
A53: BetBoom Team | B53: 34 | C53: 14 | D53: 0.41176471 | E53: Yes
A54: Breeki Cheeki | B54: 35 | C54: 14 | D54: 0.4 | E54: Yes
... A261: Team Nord | B261: 1 | C261: 0 | D261: 0 | E261: No

Sheet pivot_team_win_rate
A1: qualify | B1: Yes
A3: Row Labels | B3: Win Rate
A4: InterActive Philippines | B4: 0.65
A5: PARIVISION | B5: 0.58064516
A6: REKONIX | B6: 0.57142857
A7: Xtreme Gaming | B7: 0.5
A8: Nigma Galaxy | B8: 0.46938776
A9: L1GA TEAM | B9: 0.45901639
A10: Team Antares | B10: 0.45454545
A11: GLYPH | B11: 0.43478261
A12: BetBoom Team | B12: 0.41176471
A13: Team Nemesis | B13: 0.41176471
A14: Grand Total | B14: 0.49433354

Sheet hero_lane_summary
A1: hero_name | B1: role_name | C1: times_picked | D1: times_won | E1: win_rate | F1: qualify | G1: lane_rank | H1: tier | L1: =_xlfn.MAXIFS(hero_lane_summary!E:E, F:F, "Yes") -> 0.81818182
A2: Pudge | B2: Carry | C2: 22 | D2: 18 | E2: 0.81818182 | F2: Yes | G2: 1 | H2: {=IF(F2:F541="No","N/A", IF(E2:E541>=0.65,"S", IF(E2:E541>=0.55,"A", IF(E2:E541>=0.48,"B", IF(E2:E541>=0.35,"C", "D") ) ) ) )} -> S | L2: =_xlfn.MINIFS(hero_lane_summary!E:E, F:F, "Yes") -> 0.21428571
A3: Abaddon | B3: Off Lane | C3: 21 | D3: 7 | E3: 0.33333333 | F3: Yes | G3: 38 | H3: D | L3: =AVERAGE(hero_lane_summary!E:E) -> 0.47856185
A4: Abaddon | B4: Hard Support | C4: 9 | D4: 3 | E4: 0.33333333 | F4: No | G4: N/A | H4: N/A
A5: Abaddon | B5: Soft Support | C5: 3 | D5: 2 | E5: 0.66666667 | F5: No | G5: N/A | H5: N/A
A6: Alchemist | B6: Mid | C6: 24 | D6: 15 | E6: 0.625 | F6: Yes | G6: 2 | H6: A
A7: Phoenix | B7: Carry | C7: 10 | D7: 7 | E7: 0.7 | F7: Yes | G7: 2 | H7: S
A8: Alchemist | B8: Soft Support | C8: 4 | D8: 2 | E8: 0.5 | F8: No | G8: N/A | H8: N/A
A9: Alchemist | B9: Off Lane | C9: 28 | D9: 16 | E9: 0.57142857 | F9: Yes | G9: 6 | H9: A
A10: Alchemist | B10: Roam | C10: 1 | D10: 1 | E10: 1 | F10: No | G10: N/A | H10: N/A
A11: Ancient Apparition | B11: Hard Support | C11: 33 | D11: 16 | E11: 0.48484848 | F11: Yes | G11: 21 | H11: B
A12: Ancient Apparition | B12: Soft Support | C12: 25 | D12: 9 | E12: 0.36 | F12: Yes | G12: 38 | H12: C
A13: Ancient Apparition | B13: Roam | C13: 7 | D13: 4 | E13: 0.57142857 | F13: No | G13: N/A | H13: N/A
A14: Lone Druid | B14: Carry | C14: 106 | D14: 69 | E14: 0.6509434 | F14: Yes | G14: 3 | H14: S
A15: Anti-Mage | B15: Off Lane | C15: 11 | D15: 3 | E15: 0.27272727 | F15: Yes | G15: 39 | H15: D
A16: Anti-Mage | B16: Mid | C16: 1 | D16: 1 | E16: 1 | F16: No | G16: N/A | H16: N/A
A17: Arc Warden | B17: Mid | C17: 13 | D17: 8 | E17: 0.61538462 | F17: Yes | G17: 3 | H17: A
A18: Axe | B18: Off Lane | C18: 204 | D18: 98 | E18: 0.48039216 | F18: Yes | G18: 23 | H18: B
A19: Axe | B19: Soft Support | C19: 7 | D19: 3 | E19: 0.42857143 | F19: No | G19: N/A | H19: N/A
A20: Bane | B20: Hard Support | C20: 42 | D20: 21 | E20: 0.5 | F20: Yes | G20: 19 | H20: B
A21: Bane | B21: Soft Support | C21: 22 | D21: 15 | E21: 0.68181818 | F21: Yes | G21: 5 | H21: S
A22: Bane | B22: Roam | C22: 5 | D22: 3 | E22: 0.6 | F22: No | G22: N/A | H22: N/A
A23: Batrider | B23: Off Lane | C23: 157 | D23: 100 | E23: 0.63694268 | F23: Yes | G23: 3 | H23: A
A24: Batrider | B24: Soft Support | C24: 63 | D24: 33 | E24: 0.52380952 | F24: Yes | G24: 17 | H24: B
A25: Batrider | B25: Roam | C25: 17 | D25: 6 | E25: 0.35294118 | F25: Yes | G25: 25 | H25: C
A26: Batrider | B26: Mid | C26: 28 | D26: 15 | E26: 0.53571429 | F26: Yes | G26: 15 | H26: B
A27: Batrider | B27: Hard Support | C27: 14 | D27: 9 | E27: 0.64285714 | F27: Yes | G27: 5 | H27: A
A28: Batrider | B28: Carry | C28: 4 | D28: 2 | E28: 0.5 | F28: No | G28: N/A | H28: N/A
A29: Beastmaster | B29: Off Lane | C29: 162 | D29: 80 | E29: 0.49382716 | F29: Yes | G29: 22 | H29: B
A30: Beastmaster | B30: Mid | C30: 151 | D30: 72 | E30: 0.47682119 | F30: Yes | G30: 28 | H30: C
A31: Naga Siren | B31: Carry | C31: 30 | D31: 19 | E31: 0.63333333 | F31: Yes | G31: 4 | H31: A
A32: Beastmaster | B32: Soft Support | C32: 3 | D32: 1 | E32: 0.33333333 | F32: No | G32: N/A | H32: N/A
A33: Sniper | B33: Carry | C33: 51 | D33: 31 | E33: 0.60784314 | F33: Yes | G33: 5 | H33: A
A34: Bloodseeker | B34: Off Lane | C34: 1 | D34: 1 | E34: 1 | F34: No | G34: N/A | H34: N/A
A35: Bounty Hunter | B35: Roam | C35: 14 | D35: 8 | E35: 0.57142857 | F35: Yes | G35: 5 | H35: A
A36: Bounty Hunter | B36: Soft Support | C36: 16 | D36: 12 | E36: 0.75 | F36: Yes | G36: 1 | H36: S
A37: Bounty Hunter | B37: Mid | C37: 2 | D37: 0 | E37: 0 | F37: No | G37: N/A | H37: N/A
A38: Bounty Hunter | B38: Hard Support | C38: 6 | D38: 2 | E38: 0.33333333 | F38: No | G38: N/A | H38: N/A
A39: Bounty Hunter | B39: Off Lane | C39: 3 | D39: 3 | E39: 1 | F39: No | G39: N/A | H39: N/A
A40: Brewmaster | B40: Off Lane | C40: 111 | D40: 47 | E40: 0.42342342 | F40: Yes | G40: 31 | H40: C
...

Sheet hero_summary
A1: hero_name | B1: times_picked | C1: times_banned | D1: pick_rate | E1: ban_rate | F1: times_won | G1: win_rate | H1: score | I1: tier
A2: Abaddon | B2: 56 | C2: 310 | D2: 0.011231448 | E2: 0.062174087 | F2: 19 | G2: 0.33928571 | H2: 0.18799424 | I2: D
A3: Alchemist | B3: 303 | C3: 1092 | D3: 0.060770156 | E3: 0.21901324 | F3: 160 | G3: 0.52805281 | H3: 0.33397225 | I3: A
A4: Ancient Apparition | B4: 65 | C4: 65 | D4: 0.013036502 | E4: 0.013036502 | F4: 29 | G4: 0.44615385 | H4: 0.22959517 | I4: C
A5: Anti-Mage | B5: 70 | C5: 91 | D5: 0.01403931 | E5: 0.018251103 | F5: 36 | G5: 0.51428571 | H5: 0.26521546 | I5: C
A6: Arc Warden | B6: 13 | C6: 198 | D6: 0.0026073004 | E6: 0.039711191 | F6: 8 | G6: 0.61538462 | H6: 0.31827193 | I6: A
A7: Axe | B7: 211 | C7: 120 | D7: 0.042318492 | E7: 0.024067389 | F7: 101 | G7: 0.47867299 | H7: 0.25593296 | I7: C
A8: Bane | B8: 69 | C8: 199 | D8: 0.013838748 | E8: 0.039911753 | F8: 39 | G8: 0.56521739 | H8: 0.29604632 | I8: B
A9: Batrider | B9: 281 | C9: 1455 | D9: 0.056357802 | E9: 0.29181709 | F9: 165 | G9: 0.58718861 | H9: 0.38063803 | I9: S
A10: Beastmaster | B10: 416 | C10: 1082 | D10: 0.083433614 | E10: 0.21700762 | F10: 208 | G10: 0.5 | H10: 0.32511031 | I10: A
A11: Bloodseeker | B11: 21 | C11: 72 | D11: 0.004211793 | E11: 0.014440433 | F11: 9 | G11: 0.42857143 | H11: 0.21894877 | I11: D
A12: Bounty Hunter | B12: 41 | C12: 36 | D12: 0.0082230245 | E12: 0.0072202166 | F12: 25 | G12: 0.6097561 | H12: 0.30873886 | I12: A
A13: Brewmaster | B13: 117 | C13: 402 | D13: 0.023465704 | E13: 0.080625752 | F13: 50 | G13: 0.42735043 | H13: 0.23969808 | I13: C
... A128: Zeus | B128: 170 | C128: 196 | D128: 0.034095467 | E128: 0.039310068 | F128: 83 | G128: 0.48823529 | H128: 0.26246903 | I128: C

Sheet pivot_win_rate
A1: role_name | B1: (All)
A3: Row Labels | B3: Times won | C3: Times Picked
A4: Luna | B4: 220 | C4: 438
A5: Lion | B5: 209 | C5: 438
A6: Shadow Fiend | B6: 204 | C6: 450
A7: Disruptor | B7: 206 | C7: 450
A8: Queen of Pain | B8: 238 | C8: 484
A9: Tusk | B9: 293 | C9: 541
A10: Hoodwink | B10: 285 | C10: 543
A11: Tidehunter | B11: 269 | C11: 577
A12: Phoenix | B12: 354 | C12: 591
A13: Pangolier | B13: 342 | C13: 643
A14: Rubick | B14: 547 | C14: 1070
A15: Grand Total | B15: 3167 | C15: 6225

Sheet pivot_ban_rate
A3: Row Labels | B3: Sum of times_banned
A4: Batrider | B4: 1455
A5: Pangolier | B5: 1127
A6: Alchemist | B6: 1092
A7: Beastmaster | B7: 1082
A8: Doom | B8: 921
A9: Phoenix | B9: 835
A10: Void Spirit | B10: 813
A11: Puck | B11: 795
A12: Venomancer | B12: 781
A13: Queen of Pain | B13: 738
A14: Grand Total | B14: 9639
